"""
Failure Scenarios and Error Recovery Testing
Part of Task 18: Integration Testing and System Validation

This module provides tests for:
- Browser session failure recovery
- API service failure recovery
- Database connection failure recovery
- Workflow interruption recovery
- Network failure handling
- Rate limiting and throttling scenarios
"""
import asyncio
import pytest
import time
from datetime import datetime, timedelta
from decimal import Decimal
from unittest.mock import Mock, AsyncMock, patch, MagicMock
from typing import List, Dict, Any
import random

import sys
import os
sys.path.append(os.path.join(os.path.dirname(__file__), '..'))

from api.database.connection import get_db, init_db
from api.database.models import JobModel, ProposalModel, ApplicationModel
from shared.models import JobStatus, JobType, ProposalStatus, ApplicationStatus


class TestBrowserSessionFailures:
    """Test browser session failure scenarios and recovery"""
    
    @pytest.mark.asyncio
    async def test_session_timeout_recovery(self):
        """Test recovery from browser session timeouts"""
        mock_browserbase = Mock()
        
        # Simulate session timeout scenarios
        timeout_sessions = ["session_1", "session_2", "session_3"]
        
        def mock_health_check(session_id):
            if session_id in timeout_sessions:
                return {
                    "healthy": False,
                    "error": "Session timeout after 30 minutes",
                    "last_activity": (datetime.utcnow() - timedelta(minutes=35)).isoformat()
                }
            return {"healthy": True, "last_activity": datetime.utcnow().isoformat()}
        
        mock_browserbase.get_session_health.side_effect = mock_health_check
        
        # Mock session refresh with retry logic
        refresh_attempts = {}
        
        async def mock_refresh_session(session_id):
            if session_id not in refresh_attempts:
                refresh_attempts[session_id] = 0
            
            refresh_attempts[session_id] += 1
            
            # Fail first attempt, succeed on second
            if refresh_attempts[session_id] == 1:
                raise Exception("Refresh failed: Network timeout")
            else:
                return f"refreshed_{session_id}"
        
        mock_browserbase.refresh_session.side_effect = mock_refresh_session
        
        # Test recovery process
        recovered_sessions = {}
        
        for session_id in timeout_sessions:
            health = mock_browserbase.get_session_health(session_id)
            
            if not health["healthy"]:
                # Attempt recovery with retry logic
                max_retries = 3
                for attempt in range(max_retries):
                    try:
                        new_session = await mock_browserbase.refresh_session(session_id)
                        recovered_sessions[session_id] = new_session
                        break
                    except Exception as e:
                        if attempt < max_retries - 1:
                            await asyncio.sleep(0.1 * (2 ** attempt))  # Exponential backoff
                            continue
                        else:
                            recovered_sessions[session_id] = None
        
        # Verify recovery
        assert len(recovered_sessions) == len(timeout_sessions)
        successful_recoveries = [s for s in recovered_sessions.values() if s is not None]
        assert len(successful_recoveries) == len(timeout_sessions)
        
        # Verify retry logic was used
        for session_id in timeout_sessions:
            assert refresh_attempts[session_id] == 2  # Should have retried once
        
        print("✅ Session timeout recovery test passed")
    
    @pytest.mark.asyncio
    async def test_browser_crash_recovery(self):
        """Test recovery from browser crashes"""
        mock_browserbase = Mock()
        mock_session_manager = Mock()
        
        # Simulate browser crash scenarios
        crashed_sessions = {
            "session_crash_1": {"error": "Browser process terminated unexpectedly", "recoverable": True},
            "session_crash_2": {"error": "Out of memory error", "recoverable": True},
            "session_crash_3": {"error": "GPU driver crash", "recoverable": False}
        }
        
        def mock_health_check(session_id):
            if session_id in crashed_sessions:
                crash_info = crashed_sessions[session_id]
                return {
                    "healthy": False,
                    "error": crash_info["error"],
                    "recoverable": crash_info["recoverable"]
                }
            return {"healthy": True}
        
        mock_browserbase.get_session_health.side_effect = mock_health_check
        
        # Mock session recreation
        mock_browserbase.create_session.return_value = "new_session_123"
        
        # Mock session context preservation
        session_contexts = {
            "session_crash_1": {"login_state": "authenticated", "current_page": "job_search"},
            "session_crash_2": {"login_state": "authenticated", "current_page": "application_form"},
            "session_crash_3": {"login_state": "authenticated", "current_page": "profile"}
        }
        
        def mock_get_context(session_id):
            return session_contexts.get(session_id, {})
        
        mock_browserbase.get_session_context.side_effect = mock_get_context
        
        # Test crash recovery
        recovery_results = {}
        
        for session_id in crashed_sessions.keys():
            health = mock_browserbase.get_session_health(session_id)
            
            if not health["healthy"]:
                if health.get("recoverable", True):
                    # Preserve context before creating new session
                    context = mock_browserbase.get_session_context(session_id)
                    
                    # Create new session
                    new_session = await mock_browserbase.create_session({
                        "restore_context": context,
                        "reason": "crash_recovery"
                    })
                    
                    recovery_results[session_id] = {
                        "new_session": new_session,
                        "context_preserved": bool(context),
                        "recovery_successful": True
                    }
                else:
                    recovery_results[session_id] = {
                        "new_session": None,
                        "context_preserved": False,
                        "recovery_successful": False
                    }
        
        # Verify recovery results
        recoverable_sessions = [s for s, info in crashed_sessions.items() if info["recoverable"]]
        non_recoverable_sessions = [s for s, info in crashed_sessions.items() if not info["recoverable"]]
        
        for session_id in recoverable_sessions:
            assert recovery_results[session_id]["recovery_successful"]
            assert recovery_results[session_id]["new_session"] is not None
            assert recovery_results[session_id]["context_preserved"]
        
        for session_id in non_recoverable_sessions:
            assert not recovery_results[session_id]["recovery_successful"]
        
        print("✅ Browser crash recovery test passed")
    
    @pytest.mark.asyncio
    async def test_network_interruption_recovery(self):
        """Test recovery from network interruptions"""
        mock_browserbase = Mock()
        
        # Simulate network interruption scenarios
        network_errors = [
            "Connection reset by peer",
            "DNS resolution failed",
            "Request timeout",
            "SSL handshake failed"
        ]
        
        # Mock network operations with intermittent failures
        operation_attempts = {}
        
        async def mock_network_operation(operation_type: str, session_id: str):
            key = f"{operation_type}_{session_id}"
            if key not in operation_attempts:
                operation_attempts[key] = 0
            
            operation_attempts[key] += 1
            
            # Simulate network failures on first few attempts
            if operation_attempts[key] <= 2:
                error = random.choice(network_errors)
                raise Exception(f"Network error: {error}")
            else:
                return {"success": True, "operation": operation_type, "attempts": operation_attempts[key]}
        
        # Test network operation with retry logic
        async def network_operation_with_retry(operation_type: str, session_id: str, max_retries: int = 5):
            for attempt in range(max_retries):
                try:
                    result = await mock_network_operation(operation_type, session_id)
                    return result
                except Exception as e:
                    if attempt < max_retries - 1:
                        # Exponential backoff with jitter
                        delay = (2 ** attempt) + random.uniform(0, 1)
                        await asyncio.sleep(min(delay, 10))  # Cap at 10 seconds
                        continue
                    else:
                        raise e
        
        # Test different network operations
        operations = [
            ("page_navigation", "session_1"),
            ("form_submission", "session_2"),
            ("content_extraction", "session_3"),
            ("screenshot_capture", "session_4")
        ]
        
        results = []
        for operation_type, session_id in operations:
            try:
                result = await network_operation_with_retry(operation_type, session_id)
                results.append(result)
            except Exception as e:
                results.append({"success": False, "error": str(e)})
        
        # Verify recovery
        successful_operations = [r for r in results if r.get("success")]
        assert len(successful_operations) == len(operations)
        
        # Verify retry logic was used
        for result in successful_operations:
            assert result["attempts"] > 1  # Should have retried
            assert result["attempts"] <= 3  # Should succeed within 3 attempts
        
        print("✅ Network interruption recovery test passed")


class TestAPIServiceFailures:
    """Test external API service failure scenarios"""
    
    @pytest.mark.asyncio
    async def test_openai_api_failure_recovery(self):
        """Test recovery from OpenAI API failures"""
        # Mock different OpenAI API failure scenarios
        api_failures = [
            {"error": "Rate limit exceeded", "retry_after": 1, "recoverable": True},
            {"error": "Service unavailable", "retry_after": 2, "recoverable": True},
            {"error": "Invalid API key", "retry_after": 0, "recoverable": False},
            {"error": "Model overloaded", "retry_after": 5, "recoverable": True}
        ]
        
        call_attempts = {}
        
        async def mock_openai_call(prompt: str, failure_type: int = 0):
            if failure_type not in call_attempts:
                call_attempts[failure_type] = 0
            
            call_attempts[failure_type] += 1
            failure = api_failures[failure_type]
            
            # Fail first few attempts for recoverable errors
            if failure["recoverable"] and call_attempts[failure_type] <= 2:
                await asyncio.sleep(failure["retry_after"])
                raise Exception(failure["error"])
            elif not failure["recoverable"]:
                raise Exception(failure["error"])
            else:
                return {
                    "choices": [{"message": {"content": f"Generated response for: {prompt}"}}],
                    "usage": {"total_tokens": 100}
                }
        
        # Test recovery logic for each failure type
        async def api_call_with_retry(prompt: str, failure_type: int, max_retries: int = 3):
            for attempt in range(max_retries):
                try:
                    result = await mock_openai_call(prompt, failure_type)
                    return {"success": True, "result": result, "attempts": attempt + 1}
                except Exception as e:
                    if "Rate limit" in str(e) or "Service unavailable" in str(e) or "overloaded" in str(e):
                        if attempt < max_retries - 1:
                            # Exponential backoff for recoverable errors
                            delay = min(2 ** attempt, 30)  # Cap at 30 seconds
                            await asyncio.sleep(delay)
                            continue
                    
                    # Non-recoverable error or max retries reached
                    return {"success": False, "error": str(e), "attempts": attempt + 1}
        
        # Test each failure scenario
        recovery_results = []
        for i, failure in enumerate(api_failures):
            result = await api_call_with_retry(f"Test prompt {i}", i)
            recovery_results.append({
                "failure_type": failure["error"],
                "recoverable": failure["recoverable"],
                "result": result
            })
        
        # Verify recovery behavior
        for i, recovery in enumerate(recovery_results):
            failure = api_failures[i]
            
            if failure["recoverable"]:
                assert recovery["result"]["success"], f"Should recover from {failure['error']}"
                assert recovery["result"]["attempts"] > 1, "Should have retried"
            else:
                assert not recovery["result"]["success"], f"Should not recover from {failure['error']}"
        
        print("✅ OpenAI API failure recovery test passed")
    
    @pytest.mark.asyncio
    async def test_google_services_failure_recovery(self):
        """Test recovery from Google Services API failures"""
        # Mock Google API failure scenarios
        google_failures = {
            "docs": [
                {"error": "Quota exceeded", "code": 429, "recoverable": True},
                {"error": "Service unavailable", "code": 503, "recoverable": True},
                {"error": "Invalid credentials", "code": 401, "recoverable": False}
            ],
            "drive": [
                {"error": "File not found", "code": 404, "recoverable": False},
                {"error": "Permission denied", "code": 403, "recoverable": False},
                {"error": "Internal server error", "code": 500, "recoverable": True}
            ]
        }
        
        service_attempts = {}
        
        async def mock_google_api_call(service: str, operation: str, failure_index: int = 0):
            key = f"{service}_{operation}_{failure_index}"
            if key not in service_attempts:
                service_attempts[key] = 0
            
            service_attempts[key] += 1
            failure = google_failures[service][failure_index]
            
            # Simulate failure behavior
            if failure["recoverable"] and service_attempts[key] <= 2:
                if failure["code"] == 429:  # Rate limit
                    await asyncio.sleep(1)  # Simulate rate limit delay
                raise Exception(f"HTTP {failure['code']}: {failure['error']}")
            elif not failure["recoverable"]:
                raise Exception(f"HTTP {failure['code']}: {failure['error']}")
            else:
                return {
                    "success": True,
                    "service": service,
                    "operation": operation,
                    "attempts": service_attempts[key]
                }
        
        # Test Google Docs operations
        docs_operations = [
            ("create_document", 0),  # Quota exceeded
            ("update_document", 1),  # Service unavailable
            ("get_document", 2)      # Invalid credentials
        ]
        
        docs_results = []
        for operation, failure_index in docs_operations:
            try:
                result = await mock_google_api_call("docs", operation, failure_index)
                docs_results.append(result)
            except Exception as e:
                docs_results.append({"success": False, "error": str(e), "operation": operation})
        
        # Test Google Drive operations
        drive_operations = [
            ("search_files", 0),     # File not found
            ("upload_file", 1),      # Permission denied
            ("download_file", 2)     # Internal server error
        ]
        
        drive_results = []
        for operation, failure_index in drive_operations:
            try:
                result = await mock_google_api_call("drive", operation, failure_index)
                drive_results.append(result)
            except Exception as e:
                drive_results.append({"success": False, "error": str(e), "operation": operation})
        
        # Verify recovery behavior
        # Docs: First two should recover, third should fail
        assert docs_results[0]["success"]  # Quota exceeded - recoverable
        assert docs_results[1]["success"]  # Service unavailable - recoverable
        assert not docs_results[2]["success"]  # Invalid credentials - not recoverable
        
        # Drive: First two should fail, third should recover
        assert not drive_results[0]["success"]  # File not found - not recoverable
        assert not drive_results[1]["success"]  # Permission denied - not recoverable
        assert drive_results[2]["success"]  # Internal server error - recoverable
        
        print("✅ Google Services failure recovery test passed")
    
    @pytest.mark.asyncio
    async def test_slack_api_failure_recovery(self):
        """Test recovery from Slack API failures"""
        # Mock Slack API failure scenarios
        slack_failures = [
            {"error": "rate_limited", "retry_after": 30, "recoverable": True},
            {"error": "channel_not_found", "retry_after": 0, "recoverable": False},
            {"error": "invalid_auth", "retry_after": 0, "recoverable": False},
            {"error": "internal_error", "retry_after": 1, "recoverable": True}
        ]
        
        slack_attempts = {}
        
        async def mock_slack_api_call(channel: str, message: str, failure_type: int = 0):
            if failure_type not in slack_attempts:
                slack_attempts[failure_type] = 0
            
            slack_attempts[failure_type] += 1
            failure = slack_failures[failure_type]
            
            # Simulate failure behavior
            if failure["recoverable"] and slack_attempts[failure_type] <= 2:
                if failure["retry_after"] > 0:
                    await asyncio.sleep(failure["retry_after"] / 10)  # Reduced for testing
                raise Exception(failure["error"])
            elif not failure["recoverable"]:
                raise Exception(failure["error"])
            else:
                return {
                    "ok": True,
                    "channel": channel,
                    "ts": "1234567890.123456",
                    "attempts": slack_attempts[failure_type]
                }
        
        # Test Slack notification with retry logic
        async def send_slack_notification_with_retry(channel: str, message: str, failure_type: int):
            max_retries = 3
            for attempt in range(max_retries):
                try:
                    result = await mock_slack_api_call(channel, message, failure_type)
                    return {"success": True, "result": result}
                except Exception as e:
                    error_msg = str(e)
                    
                    # Determine if error is recoverable
                    if error_msg in ["rate_limited", "internal_error"]:
                        if attempt < max_retries - 1:
                            # Wait before retry
                            delay = 2 ** attempt
                            await asyncio.sleep(delay)
                            continue
                    
                    # Non-recoverable or max retries reached
                    return {"success": False, "error": error_msg}
        
        # Test each failure scenario
        notification_results = []
        for i, failure in enumerate(slack_failures):
            result = await send_slack_notification_with_retry("#test", f"Test message {i}", i)
            notification_results.append({
                "failure_type": failure["error"],
                "recoverable": failure["recoverable"],
                "result": result
            })
        
        # Verify recovery behavior
        for i, notification in enumerate(notification_results):
            failure = slack_failures[i]
            
            if failure["recoverable"]:
                assert notification["result"]["success"], f"Should recover from {failure['error']}"
            else:
                assert not notification["result"]["success"], f"Should not recover from {failure['error']}"
        
        print("✅ Slack API failure recovery test passed")


class TestDatabaseFailures:
    """Test database failure scenarios and recovery"""
    
    @pytest.mark.asyncio
    async def test_connection_pool_exhaustion_recovery(self):
        """Test recovery from database connection pool exhaustion"""
        # Mock database connection pool
        max_connections = 5
        active_connections = []
        
        class MockConnection:
            def __init__(self, conn_id):
                self.conn_id = conn_id
                self.in_use = False
            
            async def __aenter__(self):
                if len([c for c in active_connections if c.in_use]) >= max_connections:
                    raise Exception("Connection pool exhausted")
                self.in_use = True
                return self
            
            async def __aexit__(self, exc_type, exc_val, exc_tb):
                self.in_use = False
        
        # Create connection pool
        for i in range(max_connections):
            active_connections.append(MockConnection(i))
        
        async def get_db_connection_with_retry(max_retries: int = 3):
            for attempt in range(max_retries):
                try:
                    # Try to get an available connection
                    available_conn = next((c for c in active_connections if not c.in_use), None)
                    if available_conn:
                        return available_conn
                    else:
                        raise Exception("Connection pool exhausted")
                except Exception as e:
                    if attempt < max_retries - 1:
                        # Wait for connections to be released
                        await asyncio.sleep(0.1 * (2 ** attempt))
                        continue
                    else:
                        raise e
        
        # Test concurrent database operations
        async def database_operation(operation_id: int):
            try:
                conn = await get_db_connection_with_retry()
                async with conn:
                    # Simulate database work
                    await asyncio.sleep(0.1)
                    return {"operation_id": operation_id, "success": True, "conn_id": conn.conn_id}
            except Exception as e:
                return {"operation_id": operation_id, "success": False, "error": str(e)}
        
        # Execute more operations than available connections
        operations = [database_operation(i) for i in range(10)]
        results = await asyncio.gather(*operations)
        
        # Verify that operations eventually succeed through retry logic
        successful_ops = [r for r in results if r["success"]]
        failed_ops = [r for r in results if not r["success"]]
        
        # Most operations should succeed due to retry logic
        assert len(successful_ops) >= 8  # At least 80% success rate
        assert len(failed_ops) <= 2  # At most 20% failure rate
        
        print(f"✅ Connection pool exhaustion recovery: {len(successful_ops)} successful, {len(failed_ops)} failed")
    
    @pytest.mark.asyncio
    async def test_transaction_rollback_recovery(self):
        """Test recovery from transaction failures"""
        await init_db()
        
        # Test transaction rollback scenarios
        async def failing_transaction_operation():
            async with get_db() as session:
                try:
                    # Create a job
                    job = JobModel(
                        upwork_job_id="rollback_test_job",
                        title="Test Rollback Job",
                        description="Test job for rollback",
                        job_type=JobType.HOURLY,
                        client_rating=Decimal("4.0"),
                        client_payment_verified=True,
                        client_hire_rate=Decimal("0.5")
                    )
                    session.add(job)
                    await session.flush()  # Flush but don't commit
                    
                    # Simulate an error that causes rollback
                    raise Exception("Simulated transaction error")
                    
                except Exception as e:
                    await session.rollback()
                    raise e
        
        # Test transaction with retry logic
        async def transaction_with_retry(max_retries: int = 3):
            for attempt in range(max_retries):
                try:
                    await failing_transaction_operation()
                    return {"success": True, "attempts": attempt + 1}
                except Exception as e:
                    if attempt < max_retries - 1:
                        await asyncio.sleep(0.1)
                        continue
                    else:
                        return {"success": False, "error": str(e), "attempts": attempt + 1}
        
        # Test successful transaction after failures
        async def successful_transaction_after_failures():
            # First, try the failing transaction
            result = await transaction_with_retry()
            assert not result["success"]  # Should fail
            
            # Then, try a successful transaction
            async with get_db() as session:
                job = JobModel(
                    upwork_job_id="successful_job_after_rollback",
                    title="Successful Job After Rollback",
                    description="This should succeed",
                    job_type=JobType.HOURLY,
                    client_rating=Decimal("4.0"),
                    client_payment_verified=True,
                    client_hire_rate=Decimal("0.5")
                )
                session.add(job)
                await session.commit()
                await session.refresh(job)
                return job.id
        
        # Execute test
        job_id = await successful_transaction_after_failures()
        assert job_id is not None
        
        # Verify the successful job was saved
        async with get_db() as session:
            from sqlalchemy import select
            result = await session.execute(
                select(JobModel).where(JobModel.upwork_job_id == "successful_job_after_rollback")
            )
            saved_job = result.scalar_one_or_none()
            assert saved_job is not None
            assert saved_job.title == "Successful Job After Rollback"
        
        # Cleanup
        async with get_db() as session:
            from sqlalchemy import delete
            await session.execute(delete(JobModel).where(JobModel.upwork_job_id.like("%rollback%")))
            await session.commit()
        
        print("✅ Transaction rollback recovery test passed")


class TestWorkflowInterruptions:
    """Test workflow interruption and recovery scenarios"""
    
    @pytest.mark.asyncio
    async def test_workflow_checkpoint_recovery(self):
        """Test workflow recovery from checkpoints"""
        # Mock workflow state
        workflow_state = {
            "execution_id": "exec_123",
            "workflow_id": "job_discovery_parallel",
            "status": "running",
            "current_step": "search_agentforce",
            "progress": 0.6,
            "checkpoints": [],
            "step_results": {
                "search_salesforce": {"jobs_found": 15, "completed": True},
                "search_ai": {"jobs_found": 8, "completed": True}
            }
        }
        
        # Mock checkpoint creation
        def create_checkpoint():
            checkpoint = {
                "timestamp": datetime.utcnow().isoformat(),
                "step": workflow_state["current_step"],
                "progress": workflow_state["progress"],
                "step_results": workflow_state["step_results"].copy(),
                "checkpoint_id": f"checkpoint_{len(workflow_state['checkpoints']) + 1}"
            }
            workflow_state["checkpoints"].append(checkpoint)
            return checkpoint
        
        # Mock workflow interruption
        def simulate_interruption(reason: str):
            workflow_state["status"] = "interrupted"
            workflow_state["error"] = reason
            workflow_state["interrupted_at"] = datetime.utcnow().isoformat()
        
        # Mock recovery from checkpoint
        def recover_from_checkpoint(checkpoint_id: str = None):
            if not workflow_state["checkpoints"]:
                return False
            
            # Use latest checkpoint if none specified
            if checkpoint_id is None:
                checkpoint = workflow_state["checkpoints"][-1]
            else:
                checkpoint = next((c for c in workflow_state["checkpoints"] if c["checkpoint_id"] == checkpoint_id), None)
                if not checkpoint:
                    return False
            
            # Restore state from checkpoint
            workflow_state["status"] = "running"
            workflow_state["current_step"] = checkpoint["step"]
            workflow_state["progress"] = checkpoint["progress"]
            workflow_state["step_results"] = checkpoint["step_results"]
            workflow_state["recovered_from"] = checkpoint["checkpoint_id"]
            workflow_state["recovered_at"] = datetime.utcnow().isoformat()
            
            return True
        
        # Test workflow with checkpointing
        # Step 1: Create initial checkpoint
        checkpoint1 = create_checkpoint()
        assert checkpoint1["step"] == "search_agentforce"
        assert checkpoint1["progress"] == 0.6
        
        # Step 2: Simulate progress and another checkpoint
        workflow_state["current_step"] = "search_einstein"
        workflow_state["progress"] = 0.8
        workflow_state["step_results"]["search_agentforce"] = {"jobs_found": 12, "completed": True}
        
        checkpoint2 = create_checkpoint()
        assert checkpoint2["step"] == "search_einstein"
        assert checkpoint2["progress"] == 0.8
        
        # Step 3: Simulate interruption
        simulate_interruption("System shutdown during execution")
        assert workflow_state["status"] == "interrupted"
        
        # Step 4: Recover from latest checkpoint
        recovery_success = recover_from_checkpoint()
        assert recovery_success is True
        assert workflow_state["status"] == "running"
        assert workflow_state["current_step"] == "search_einstein"
        assert workflow_state["progress"] == 0.8
        assert "search_agentforce" in workflow_state["step_results"]
        
        # Step 5: Test recovery from specific checkpoint
        simulate_interruption("Another interruption")
        recovery_success = recover_from_checkpoint("checkpoint_1")
        assert recovery_success is True
        assert workflow_state["current_step"] == "search_agentforce"
        assert workflow_state["progress"] == 0.6
        
        print("✅ Workflow checkpoint recovery test passed")
    
    @pytest.mark.asyncio
    async def test_partial_workflow_completion_recovery(self):
        """Test recovery when workflow is partially completed"""
        # Mock multi-step workflow
        workflow_steps = [
            {"id": "step_1", "name": "Initialize", "status": "completed", "result": {"initialized": True}},
            {"id": "step_2", "name": "Search Jobs", "status": "completed", "result": {"jobs_found": 25}},
            {"id": "step_3", "name": "Filter Jobs", "status": "running", "result": None},
            {"id": "step_4", "name": "Generate Proposals", "status": "pending", "result": None},
            {"id": "step_5", "name": "Submit Applications", "status": "pending", "result": None}
        ]
        
        # Mock workflow execution with interruption
        async def execute_workflow_step(step):
            if step["status"] == "completed":
                return step["result"]
            elif step["status"] == "running":
                # Simulate interruption during execution
                if step["id"] == "step_3":
                    await asyncio.sleep(0.1)
                    raise Exception("Workflow interrupted during step execution")
            elif step["status"] == "pending":
                # Should not be executed yet
                raise Exception("Attempting to execute pending step")
        
        # Test recovery logic
        async def recover_and_continue_workflow():
            completed_steps = [s for s in workflow_steps if s["status"] == "completed"]
            interrupted_step = next((s for s in workflow_steps if s["status"] == "running"), None)
            pending_steps = [s for s in workflow_steps if s["status"] == "pending"]
            
            recovery_state = {
                "completed_count": len(completed_steps),
                "interrupted_step": interrupted_step["id"] if interrupted_step else None,
                "pending_count": len(pending_steps),
                "can_resume": interrupted_step is not None
            }
            
            # Simulate resuming from interrupted step
            if recovery_state["can_resume"]:
                try:
                    # Reset interrupted step and try again
                    interrupted_step["status"] = "pending"
                    
                    # Mock successful completion of interrupted step
                    interrupted_step["status"] = "completed"
                    interrupted_step["result"] = {"filtered_jobs": 18}
                    
                    recovery_state["resumed_successfully"] = True
                    recovery_state["remaining_steps"] = len(pending_steps) - 1  # Minus the one we just completed
                    
                except Exception as e:
                    recovery_state["resumed_successfully"] = False
                    recovery_state["error"] = str(e)
            
            return recovery_state
        
        # Execute recovery test
        recovery_result = await recover_and_continue_workflow()
        
        # Verify recovery state
        assert recovery_result["completed_count"] == 2  # Steps 1 and 2 were completed
        assert recovery_result["interrupted_step"] == "step_3"
        assert recovery_result["can_resume"] is True
        assert recovery_result["resumed_successfully"] is True
        assert recovery_result["remaining_steps"] == 2  # Steps 4 and 5 still pending
        
        # Verify step state after recovery
        step_3 = next(s for s in workflow_steps if s["id"] == "step_3")
        assert step_3["status"] == "completed"
        assert step_3["result"]["filtered_jobs"] == 18
        
        print("✅ Partial workflow completion recovery test passed")


class TestRateLimitingScenarios:
    """Test rate limiting and throttling scenarios"""
    
    @pytest.mark.asyncio
    async def test_api_rate_limit_handling(self):
        """Test handling of API rate limits"""
        # Mock rate-limited API
        api_call_count = 0
        rate_limit_window = 60  # seconds
        rate_limit_max_calls = 10
        
        async def mock_rate_limited_api_call():
            nonlocal api_call_count
            api_call_count += 1
            
            if api_call_count > rate_limit_max_calls:
                raise Exception("Rate limit exceeded: 10 calls per minute")
            
            return {"success": True, "call_number": api_call_count}
        
        # Test rate limit handling with backoff
        async def api_call_with_rate_limit_handling():
            max_retries = 3
            base_delay = 1
            
            for attempt in range(max_retries):
                try:
                    result = await mock_rate_limited_api_call()
                    return {"success": True, "result": result, "attempts": attempt + 1}
                except Exception as e:
                    if "Rate limit exceeded" in str(e):
                        if attempt < max_retries - 1:
                            # Exponential backoff for rate limits
                            delay = base_delay * (2 ** attempt)
                            await asyncio.sleep(delay / 10)  # Reduced for testing
                            
                            # Reset call count to simulate rate limit window reset
                            if attempt == 1:
                                api_call_count = 0
                            
                            continue
                    
                    return {"success": False, "error": str(e), "attempts": attempt + 1}
        
        # Test multiple API calls that exceed rate limit
        results = []
        for i in range(15):  # More than rate limit
            result = await api_call_with_rate_limit_handling()
            results.append(result)
        
        # Verify rate limit handling
        successful_calls = [r for r in results if r["success"]]
        failed_calls = [r for r in results if not r["success"]]
        
        # Should have some successful calls due to retry logic
        assert len(successful_calls) > 5
        
        # Some calls should have required retries
        retry_calls = [r for r in successful_calls if r["attempts"] > 1]
        assert len(retry_calls) > 0
        
        print(f"✅ API rate limit handling: {len(successful_calls)} successful, {len(retry_calls)} with retries")
    
    @pytest.mark.asyncio
    async def test_browser_automation_throttling(self):
        """Test browser automation throttling to avoid detection"""
        # Mock browser automation with anti-bot detection
        automation_calls = []
        detection_threshold = 5  # Calls per second
        
        async def mock_browser_automation(action: str):
            current_time = time.time()
            automation_calls.append(current_time)
            
            # Check for rapid automation (anti-bot detection)
            recent_calls = [t for t in automation_calls if current_time - t < 1.0]  # Last second
            
            if len(recent_calls) > detection_threshold:
                raise Exception("Anti-bot detection triggered: Too many rapid requests")
            
            return {"success": True, "action": action, "timestamp": current_time}
        
        # Test throttled automation
        async def throttled_browser_automation(actions: List[str]):
            results = []
            min_delay = 0.2  # Minimum delay between actions
            
            for i, action in enumerate(actions):
                try:
                    if i > 0:
                        await asyncio.sleep(min_delay)  # Throttle requests
                    
                    result = await mock_browser_automation(action)
                    results.append(result)
                    
                except Exception as e:
                    # If detection triggered, increase delay and retry
                    await asyncio.sleep(1.0)  # Longer delay after detection
                    try:
                        result = await mock_browser_automation(action)
                        results.append(result)
                    except Exception as retry_error:
                        results.append({"success": False, "error": str(retry_error), "action": action})
            
            return results
        
        # Test with many automation actions
        actions = [f"action_{i}" for i in range(20)]
        results = await throttled_browser_automation(actions)
        
        # Verify throttling effectiveness
        successful_actions = [r for r in results if r["success"]]
        failed_actions = [r for r in results if not r["success"]]
        
        # Most actions should succeed due to throttling
        assert len(successful_actions) >= 18  # At least 90% success rate
        assert len(failed_actions) <= 2  # At most 10% failure rate
        
        # Verify timing between successful actions
        if len(successful_actions) > 1:
            timestamps = [r["timestamp"] for r in successful_actions]
            intervals = [timestamps[i+1] - timestamps[i] for i in range(len(timestamps)-1)]
            avg_interval = sum(intervals) / len(intervals)
            
            # Average interval should be close to our throttling delay
            assert avg_interval >= 0.15  # Should be at least close to min_delay
        
        print(f"✅ Browser automation throttling: {len(successful_actions)} successful actions with proper throttling")


if __name__ == "__main__":
    # Run failure recovery tests
    pytest.main([__file__, "-v", "-s"])